<?xml version="1.0" encoding="UTF-8"?>
<!-- Generated by org.testng.reporters.JUnitReportReporter -->
<testsuite skipped="0" hostname="DGT-SYS-013" name="com.yosi.testscript.Guantor_Info_TC" tests="4" failures="0" timestamp="24 Oct 2018 04:39:08 GMT" time="19.744" errors="1">
  <testcase name="patient_guarantor" time="2.539" classname="com.yosi.testscript.Guantor_Info_TC"/>
  <testcase name="afterClass" time="15.631" classname="com.yosi.testscript.Guantor_Info_TC">
    <error type="java.lang.NullPointerException">
      <![CDATA[java.lang.NullPointerExceptionat com.yosi.base.YosiBaseClass.medical_history_page(YosiBaseClass.java:369)at com.yosi.testscript.Guantor_Info_TC.afterClass(Guantor_Info_TC.java:144)at sun.reflect.NativeMethodAccessorImpl.invoke0(Native Method)at sun.reflect.NativeMethodAccessorImpl.invoke(Unknown Source)at sun.reflect.DelegatingMethodAccessorImpl.invoke(Unknown Source)at java.lang.reflect.Method.invoke(Unknown Source)at org.testng.internal.MethodInvocationHelper.invokeMethod(MethodInvocationHelper.java:124)at org.testng.internal.MethodInvocationHelper.invokeMethodConsideringTimeout(MethodInvocationHelper.java:59)at org.testng.internal.Invoker.invokeConfigurationMethod(Invoker.java:451)at org.testng.internal.Invoker.invokeConfigurations(Invoker.java:222)at org.testng.internal.Invoker.invokeConfigurations(Invoker.java:142)at org.testng.internal.TestMethodWorker.invokeAfterClassMethods(TestMethodWorker.java:208)at org.testng.internal.TestMethodWorker.run(TestMethodWorker.java:111)at org.testng.TestRunner.privateRun(TestRunner.java:648)at org.testng.TestRunner.run(TestRunner.java:505)at org.testng.SuiteRunner.runTest(SuiteRunner.java:455)at org.testng.SuiteRunner.runSequentially(SuiteRunner.java:450)at org.testng.SuiteRunner.privateRun(SuiteRunner.java:415)at org.testng.SuiteRunner.run(SuiteRunner.java:364)at org.testng.SuiteRunnerWorker.runSuite(SuiteRunnerWorker.java:52)at org.testng.SuiteRunnerWorker.run(SuiteRunnerWorker.java:84)at org.testng.TestNG.runSuitesSequentially(TestNG.java:1187)at org.testng.TestNG.runSuitesLocally(TestNG.java:1116)at org.testng.TestNG.runSuites(TestNG.java:1028)at org.testng.TestNG.run(TestNG.java:996)at org.testng.remote.AbstractRemoteTestNG.run(AbstractRemoteTestNG.java:114)at org.testng.remote.RemoteTestNG.initAndRun(RemoteTestNG.java:251)at org.testng.remote.RemoteTestNG.main(RemoteTestNG.java:77)]]>
    </error>
  </testcase> <!-- afterClass -->
  <testcase name="patient_guarantor" time="0.741" classname="com.yosi.testscript.Guantor_Info_TC"/>
  <testcase name="patient_guarantor" time="0.833" classname="com.yosi.testscript.Guantor_Info_TC"/>
</testsuite> <!-- com.yosi.testscript.Guantor_Info_TC -->
